Workbook

Sheet PMI_MFG_M
Q1: publish_date | S1: raw_data | T1: factor_value_level | U1: factor_value_change
Q2: 20160731 | R2: =DATE(LEFT(Q2,4),MID(Q2,5,2),RIGHT(Q2,2)) -> 42582 | S2: 49.9 | T2: 0.10453294
Q3: 20160831 | R3: =DATE(LEFT(Q3,4),MID(Q3,5,2),RIGHT(Q3,2)) -> 42613 | S3: 50.4 | T3: 1.49098 | U3: 1.187098
Q4: 20160930 | R4: =DATE(LEFT(Q4,4),MID(Q4,5,2),RIGHT(Q4,2)) -> 42643 | S4: 50.4 | T4: 1.1529241 | U4: -0.29436391
Q5: 20161031 | R5: =DATE(LEFT(Q5,4),MID(Q5,5,2),RIGHT(Q5,2)) -> 42674 | S5: 51.2 | T5: 3 | U5: 1.7503754
Q6: 20161130 | R6: =DATE(LEFT(Q6,4),MID(Q6,5,2),RIGHT(Q6,2)) -> 42704 | S6: 51.7 | T6: 3 | U6: 0.60484345
Q7: 20161231 | R7: =DATE(LEFT(Q7,4),MID(Q7,5,2),RIGHT(Q7,2)) -> 42735 | S7: 51.4 | T7: 1.5717238 | U7: -1.47869
Q8: 20170131 | R8: =DATE(LEFT(Q8,4),MID(Q8,5,2),RIGHT(Q8,2)) -> 42766 | S8: 51.3 | T8: 0.99261227 | U8: -0.71182777
Q9: 20170228 | R9: =DATE(LEFT(Q9,4),MID(Q9,5,2),RIGHT(Q9,2)) -> 42794 | S9: 51.6 | T9: 1.312166 | U9: 0.36265048
Q10: 20170331 | R10: =DATE(LEFT(Q10,4),MID(Q10,5,2),RIGHT(Q10,2)) -> 42825 | S10: 51.8 | T10: 1.3578472 | U10: 0.038787348
Q11: 20170430 | R11: =DATE(LEFT(Q11,4),MID(Q11,5,2),RIGHT(Q11,2)) -> 42855 | S11: 51.2 | T11: -0.09047164 | U11: -1.9824346
Q12: 20170531 | R12: =DATE(LEFT(Q12,4),MID(Q12,5,2),RIGHT(Q12,2)) -> 42886 | S12: 51.2 | T12: -0.15238474 | U12: -0.11711588
Q13: 20170630 | R13: =DATE(LEFT(Q13,4),MID(Q13,5,2),RIGHT(Q13,2)) -> 42916 | S13: 51.7 | T13: 0.75015287 | U13: 1.1062828
Q14: 20170731 | R14: =DATE(LEFT(Q14,4),MID(Q14,5,2),RIGHT(Q14,2)) -> 42947 | S14: 51.4 | T14: -0.041082983 | U14: -1.0378064
... Q118: 20260331 | R118: =DATE(LEFT(Q118,4),MID(Q118,5,2),RIGHT(Q118,2)) -> 46112 | S118: 50.4 | T118: 1.4630014 | U118: 1.3133111

Sheet IAV_YOY_M
A1: publish_date | C1: raw_data | D1: factor_value_level | E1: factor_value_change
A2: 20160731 | B2: =DATE(LEFT(A2,4),MID(A2,5,2),RIGHT(A2,2)) -> 42582 | C2: 6 | D2: -0.19964928
A3: 20160831 | B3: =DATE(LEFT(A3,4),MID(A3,5,2),RIGHT(A3,2)) -> 42613 | C3: 6.3 | D3: 0.37607878 | E3: 0.53009083
A4: 20160930 | B4: =DATE(LEFT(A4,4),MID(A4,5,2),RIGHT(A4,2)) -> 42643 | C4: 6.1 | D4: -0.059572821 | E4: -0.25564027
A5: 20161031 | B5: =DATE(LEFT(A5,4),MID(A5,5,2),RIGHT(A5,2)) -> 42674 | C5: 6.1 | D5: -0.050095415 | E5: 0.089181803
A6: 20161130 | B6: =DATE(LEFT(A6,4),MID(A6,5,2),RIGHT(A6,2)) -> 42704 | C6: 6.2 | D6: 0.15131792 | E6: 0.2334381
A7: 20161231 | B7: =DATE(LEFT(A7,4),MID(A7,5,2),RIGHT(A7,2)) -> 42735 | C7: 6 | D7: -0.27172374 | E7: -0.24818741
A8: 20170131 | B8: =DATE(LEFT(A8,4),MID(A8,5,2),RIGHT(A8,2)) -> 42766 | D8: 0.078033344 | E8: 0.34688903
A9: 20170228 | B9: =DATE(LEFT(A9,4),MID(A9,5,2),RIGHT(A9,2)) -> 42794 | C9: 6.3 | D9: 0.37369257 | E9: 0.29784255
A10: 20170331 | B10: =DATE(LEFT(A10,4),MID(A10,5,2),RIGHT(A10,2)) -> 42825 | C10: 7.6 | D10: 3 | E10: 2.098252
A11: 20170430 | B11: =DATE(LEFT(A11,4),MID(A11,5,2),RIGHT(A11,2)) -> 42855 | C11: 6.5 | D11: 0.12681251 | E11: -2.0143039
A12: 20170531 | B12: =DATE(LEFT(A12,4),MID(A12,5,2),RIGHT(A12,2)) -> 42886 | C12: 6.5 | D12: 0.086989318 | E12: 0.024144105
A13: 20170630 | B13: =DATE(LEFT(A13,4),MID(A13,5,2),RIGHT(A13,2)) -> 42916 | C13: 7.6 | D13: 2.1508809 | E13: 1.6307456
A14: 20170731 | B14: =DATE(LEFT(A14,4),MID(A14,5,2),RIGHT(A14,2)) -> 42947 | C14: 6.4 | D14: -0.52864302 | E14: -1.9647026
A15: 20170831 | B15: =DATE(LEFT(A15,4),MID(A15,5,2),RIGHT(A15,2)) -> 42978 | C15: 6 | D15: -1.1943467 | E15: -0.44289768
A16: 20170930 | B16: =DATE(LEFT(A16,4),MID(A16,5,2),RIGHT(A16,2)) -> 43008 | C16: 6.6 | D16: 0.09456536 | E16: 1.017833
A17: 20171031 | B17: =DATE(LEFT(A17,4),MID(A17,5,2),RIGHT(A17,2)) -> 43039 | C17: 6.2 | D17: -0.67923222 | E17: -0.53299824
A18: 20171130 | B18: =DATE(LEFT(A18,4),MID(A18,5,2),RIGHT(A18,2)) -> 43069 | C18: 6.1 | D18: -0.7666091 | E18: -0.016236219
A19: 20171231 | B19: =DATE(LEFT(A19,4),MID(A19,5,2),RIGHT(A19,2)) -> 43100 | C19: 6.2 | D19: -0.46219191 | E19: 0.27814444
A20: 20180131 | B20: =DATE(LEFT(A20,4),MID(A20,5,2),RIGHT(A20,2)) -> 43131 | D20: 0.54778426 | E20: 0.81247137
A21: 20180228 | B21: =DATE(LEFT(A21,4),MID(A21,5,2),RIGHT(A21,2)) -> 43159 | C21: 7.2 | D21: 1.5264438 | E21: 0.67670221
A22: 20180331 | B22: =DATE(LEFT(A22,4),MID(A22,5,2),RIGHT(A22,2)) -> 43190 | C22: 6 | D22: -1.1188844 | E22: -1.9005229
A23: 20180430 | B23: =DATE(LEFT(A23,4),MID(A23,5,2),RIGHT(A23,2)) -> 43220 | C23: 7 | D23: 1.0244144 | E23: 1.5798892
A24: 20180531 | B24: =DATE(LEFT(A24,4),MID(A24,5,2),RIGHT(A24,2)) -> 43251 | C24: 6.8 | D24: 0.39330987 | E24: -0.37034444
A25: 20180630 | B25: =DATE(LEFT(A25,4),MID(A25,5,2),RIGHT(A25,2)) -> 43281 | C25: 6 | D25: -1.3388109 | E25: -1.1397692
A26: 20180731 | B26: =DATE(LEFT(A26,4),MID(A26,5,2),RIGHT(A26,2)) -> 43312 | C26: 6 | D26: -1.0848548 | E26: 0.18131608
A27: 20180831 | B27: =DATE(LEFT(A27,4),MID(A27,5,2),RIGHT(A27,2)) -> 43343 | C27: 6.1 | D27: -0.70601242 | E27: 0.30033346
A28: 20180930 | B28: =DATE(LEFT(A28,4),MID(A28,5,2),RIGHT(A28,2)) -> 43373 | C28: 5.8 | D28: -1.1892476 | E28: -0.30968203
A29: 20181031 | B29: =DATE(LEFT(A29,4),MID(A29,5,2),RIGHT(A29,2)) -> 43404 | C29: 5.9 | D29: -0.81045149 | E29: 0.3237261
A30: 20181130 | B30: =DATE(LEFT(A30,4),MID(A30,5,2),RIGHT(A30,2)) -> 43434 | C30: 5.4 | D30: -1.7189449 | E30: -0.59191338
A31: 20181231 | B31: =DATE(LEFT(A31,4),MID(A31,5,2),RIGHT(A31,2)) -> 43465 | C31: 5.7 | D31: -0.77805883 | E31: 0.68449813
A32: 20190131 | B32: =DATE(LEFT(A32,4),MID(A32,5,2),RIGHT(A32,2)) -> 43496 | D32: -1.0273669 | E32: -0.15712788
A33: 20190228 | B33: =DATE(LEFT(A33,4),MID(A33,5,2),RIGHT(A33,2)) -> 43524 | C33: 5.3 | D33: -1.2401256 | E33: -0.12364783
A34: 20190331 | B34: =DATE(LEFT(A34,4),MID(A34,5,2),RIGHT(A34,2)) -> 43555 | C34: 8.5 | D34: 3 | E34: 3
A35: 20190430 | B35: =DATE(LEFT(A35,4),MID(A35,5,2),RIGHT(A35,2)) -> 43585 | C35: 5.4 | D35: -1.3574936 | E35: -3
A36: 20190531 | B36: =DATE(LEFT(A36,4),MID(A36,5,2),RIGHT(A36,2)) -> 43616 | C36: 5 | D36: -1.6777424 | E36: -0.27420421
A37: 20190630 | B37: =DATE(LEFT(A37,4),MID(A37,5,2),RIGHT(A37,2)) -> 43646 | C37: 6.3 | D37: 0.514535 | E37: 1.5767329
A38: 20190731 | B38: =DATE(LEFT(A38,4),MID(A38,5,2),RIGHT(A38,2)) -> 43677 | C38: 4.8 | D38: -1.6800195 | E38: -1.6061883
A39: 20190831 | B39: =DATE(LEFT(A39,4),MID(A39,5,2),RIGHT(A39,2)) -> 43708 | C39: 4.4 | D39: -1.868682 | E39: -0.19794609
A40: 20190930 | B40: =DATE(LEFT(A40,4),MID(A40,5,2),RIGHT(A40,2)) -> 43738 | C40: 5.8 | D40: 0.38131175 | E40: 1.6801969
...

Sheet PPI_YOY_M
A1: publish_date | C1: raw_data | D1: factor_value_level | E1: factor_value_change
A2: 20160731 | B2: =DATE(LEFT(A2,4),MID(A2,5,2),RIGHT(A2,2)) -> 42582 | C2: -1.7 | D2: 2.2674573
A3: 20160831 | B3: =DATE(LEFT(A3,4),MID(A3,5,2),RIGHT(A3,2)) -> 42613 | C3: -0.8 | D3: 2.3586611 | E3: 0.85636979
A4: 20160930 | B4: =DATE(LEFT(A4,4),MID(A4,5,2),RIGHT(A4,2)) -> 42643 | C4: 0.1 | D4: 2.3373662 | E4: 0.66283992
A5: 20161031 | B5: =DATE(LEFT(A5,4),MID(A5,5,2),RIGHT(A5,2)) -> 42674 | C5: 1.2 | D5: 2.3970816 | E5: 0.91008652
A6: 20161130 | B6: =DATE(LEFT(A6,4),MID(A6,5,2),RIGHT(A6,2)) -> 42704 | C6: 3.3 | D6: 2.9655319 | E6: 2.7264068
A7: 20161231 | B7: =DATE(LEFT(A7,4),MID(A7,5,2),RIGHT(A7,2)) -> 42735 | C7: 5.5 | D7: 3 | E7: 2.0636398
A8: 20170131 | B8: =DATE(LEFT(A8,4),MID(A8,5,2),RIGHT(A8,2)) -> 42766 | C8: 6.9 | D8: 2.7342381 | E8: 0.1611857
A9: 20170228 | B9: =DATE(LEFT(A9,4),MID(A9,5,2),RIGHT(A9,2)) -> 42794 | C9: 7.8 | D9: 2.2574273 | E9: -0.78805549
A10: 20170331 | B10: =DATE(LEFT(A10,4),MID(A10,5,2),RIGHT(A10,2)) -> 42825 | C10: 7.6 | D10: 1.5478226 | E10: -2.6059333
A11: 20170430 | B11: =DATE(LEFT(A11,4),MID(A11,5,2),RIGHT(A11,2)) -> 42855 | C11: 6.4 | D11: 0.70591154 | E11: -3
A12: 20170531 | B12: =DATE(LEFT(A12,4),MID(A12,5,2),RIGHT(A12,2)) -> 42886 | C12: 5.5 | D12: 0.1567634 | E12: -2.032618
A13: 20170630 | B13: =DATE(LEFT(A13,4),MID(A13,5,2),RIGHT(A13,2)) -> 42916 | C13: 5.5 | D13: 0.02970695 | E13: -0.46124038
A14: 20170731 | B14: =DATE(LEFT(A14,4),MID(A14,5,2),RIGHT(A14,2)) -> 42947 | C14: 5.5 | D14: -0.07786456 | E14: -0.38648758
... A118: 20260331 | B118: =DATE(LEFT(A118,4),MID(A118,5,2),RIGHT(A118,2)) -> 46112 | C118: 0.5 | D118: 1.9138549 | E118: 1.5187498

Sheet CPI_YOY_M
A1: publish_date | C1: raw_data | D1: factor_value_level | E1: factor_value_change
A2: 20160731 | B2: =DATE(LEFT(A2,4),MID(A2,5,2),RIGHT(A2,2)) -> 42582 | C2: 1.765113 | D2: -0.24853428
A3: 20160831 | B3: =DATE(LEFT(A3,4),MID(A3,5,2),RIGHT(A3,2)) -> 42613 | C3: 1.339773 | D3: -1.6334332 | E3: -1.2765487
A4: 20160930 | B4: =DATE(LEFT(A4,4),MID(A4,5,2),RIGHT(A4,2)) -> 42643 | C4: 1.920226 | D4: 0.62932766 | E4: 1.9078337
A5: 20161031 | B5: =DATE(LEFT(A5,4),MID(A5,5,2),RIGHT(A5,2)) -> 42674 | C5: 2.095947 | D5: 1.1025252 | E5: 0.32661992
A6: 20161130 | B6: =DATE(LEFT(A6,4),MID(A6,5,2),RIGHT(A6,2)) -> 42704 | C6: 2.252258 | D6: 1.4009337 | E6: 0.19967473
A7: 20161231 | B7: =DATE(LEFT(A7,4),MID(A7,5,2),RIGHT(A7,2)) -> 42735 | C7: 2.076545 | D7: 0.54027115 | E7: -0.80066903
A8: 20170131 | B8: =DATE(LEFT(A8,4),MID(A8,5,2),RIGHT(A8,2)) -> 42766 | C8: 2.549055 | D8: 1.9759961 | E8: 1.2024102
A9: 20170228 | B9: =DATE(LEFT(A9,4),MID(A9,5,2),RIGHT(A9,2)) -> 42794 | C9: 0.8 | D9: -3 | E9: -3
A10: 20170331 | B10: =DATE(LEFT(A10,4),MID(A10,5,2),RIGHT(A10,2)) -> 42825 | C10: 0.9 | D10: -2.3064265 | E10: 0.62434886
A11: 20170430 | B11: =DATE(LEFT(A11,4),MID(A11,5,2),RIGHT(A11,2)) -> 42855 | C11: 1.2 | D11: -1.0402973 | E11: 0.91727225
A12: 20170531 | B12: =DATE(LEFT(A12,4),MID(A12,5,2),RIGHT(A12,2)) -> 42886 | C12: 1.5 | D12: -0.13730526 | E12: 0.75067391
A13: 20170630 | B13: =DATE(LEFT(A13,4),MID(A13,5,2),RIGHT(A13,2)) -> 42916 | C13: 1.5 | D13: -0.094294798 | E13: 0.011198467
A14: 20170731 | B14: =DATE(LEFT(A14,4),MID(A14,5,2),RIGHT(A14,2)) -> 42947 | C14: 1.4 | D14: -0.29668178 | E14: -0.19910119
... A118: 20260331 | B118: =DATE(LEFT(A118,4),MID(A118,5,2),RIGHT(A118,2)) -> 46112 | C118: 1 | D118: 1.3863325 | E118: -0.96408004

Sheet NHCCI_D
A1: publish_date | C1: raw_data | D1: factor_value_level | E1: factor_value_change
A2: 20160731 | B2: =DATE(LEFT(A2,4),MID(A2,5,2),RIGHT(A2,2)) -> 42582 | C2: 0.46266214 | D2: 2.0606662
A3: 20160831 | B3: =DATE(LEFT(A3,4),MID(A3,5,2),RIGHT(A3,2)) -> 42613 | C3: -0.47158449 | D3: 1.838043 | E3: -0.097345066
A4: 20160930 | B4: =DATE(LEFT(A4,4),MID(A4,5,2),RIGHT(A4,2)) -> 42643 | C4: 2.6883872 | D4: 1.1630214 | E4: -1.1417989
A5: 20161031 | B5: =DATE(LEFT(A5,4),MID(A5,5,2),RIGHT(A5,2)) -> 42674 | C5: 10.058651 | D5: 1.5463829 | E5: 0.80324817
A6: 20161130 | B6: =DATE(LEFT(A6,4),MID(A6,5,2),RIGHT(A6,2)) -> 42704 | C6: 8.9449711 | D6: 3 | E6: 3
A7: 20161231 | B7: =DATE(LEFT(A7,4),MID(A7,5,2),RIGHT(A7,2)) -> 42735 | C7: -1.3691795 | D7: 2.6193397 | E7: 0.0019919825
A8: 20170131 | B8: =DATE(LEFT(A8,4),MID(A8,5,2),RIGHT(A8,2)) -> 42766 | C8: 7.8316393 | D8: 1.7908989 | E8: -1.3182182
A9: 20170228 | B9: =DATE(LEFT(A9,4),MID(A9,5,2),RIGHT(A9,2)) -> 42794 | C9: -1.1615426 | D9: 1.7879344 | E9: 0.1458738
A10: 20170331 | B10: =DATE(LEFT(A10,4),MID(A10,5,2),RIGHT(A10,2)) -> 42825 | C10: -4.1656777 | D10: 0.93747962 | E10: -2.013991
A11: 20170430 | B11: =DATE(LEFT(A11,4),MID(A11,5,2),RIGHT(A11,2)) -> 42855 | C11: -2.8780704 | D11: 0.15829921 | E11: -1.9063197
A12: 20170531 | B12: =DATE(LEFT(A12,4),MID(A12,5,2),RIGHT(A12,2)) -> 42886 | C12: -5.466951 | D12: -0.26025314 | E12: -0.97585234
A13: 20170630 | B13: =DATE(LEFT(A13,4),MID(A13,5,2),RIGHT(A13,2)) -> 42916 | C13: 5.7749369 | D13: -0.47895757 | E13: -0.50013659
A14: 20170731 | B14: =DATE(LEFT(A14,4),MID(A14,5,2),RIGHT(A14,2)) -> 42947 | C14: 7.0546506 | D14: 0.33465044 | E14: 1.7954609
... A118: 20260331 | B118: =DATE(LEFT(A118,4),MID(A118,5,2),RIGHT(A118,2)) -> 46112 | C118: 9.0186401 | D118: 3 | E118: 2.6911403

Sheet SFS_YOY_M
A1: publish_date | C1: raw_data | D1: factor_value_level | E1: factor_value_change
A2: 20170331 | B2: =DATE(LEFT(A2,4),MID(A2,5,2),RIGHT(A2,2)) -> 42825 | C2: 15.710338 | D2: 1.5547735
A3: 20170430 | B3: =DATE(LEFT(A3,4),MID(A3,5,2),RIGHT(A3,2)) -> 42855 | C3: 15.501043 | D3: 1.0290117 | E3: -0.47088739
A4: 20170531 | B4: =DATE(LEFT(A4,4),MID(A4,5,2),RIGHT(A4,2)) -> 42886 | C4: 15.503387 | D4: 0.80878746 | E4: -0.2019828
A5: 20170630 | B5: =DATE(LEFT(A5,4),MID(A5,5,2),RIGHT(A5,2)) -> 42916 | C5: 14.917823 | D5: 0.17208588 | E5: -0.69666715
A6: 20170731 | B6: =DATE(LEFT(A6,4),MID(A6,5,2),RIGHT(A6,2)) -> 42947 | C6: 15.542253 | D6: 0.61614459 | E6: 0.5411862
A7: 20170831 | B7: =DATE(LEFT(A7,4),MID(A7,5,2),RIGHT(A7,2)) -> 42978 | C7: 15.112273 | D7: 0.12261738 | E7: -0.53421341
A8: 20170930 | B8: =DATE(LEFT(A8,4),MID(A8,5,2),RIGHT(A8,2)) -> 43008 | C8: 14.888994 | D8: -0.11876675 | E8: -0.23946252
A9: 20171031 | B9: =DATE(LEFT(A9,4),MID(A9,5,2),RIGHT(A9,2)) -> 43039 | C9: 14.955353 | D9: -0.076233397 | E9: 0.087821832
A10: 20171130 | B10: =DATE(LEFT(A10,4),MID(A10,5,2),RIGHT(A10,2)) -> 43069 | C10: 14.492229 | D10: -0.50016454 | E10: -0.44313196
A11: 20171231 | B11: =DATE(LEFT(A11,4),MID(A11,5,2),RIGHT(A11,2)) -> 43100 | C11: 14.081822 | D11: -0.80763106 | E11: -0.30483555
A12: 20180131 | B12: =DATE(LEFT(A12,4),MID(A12,5,2),RIGHT(A12,2)) -> 43131 | C12: 13.433579 | D12: -1.2670214 | E12: -0.48476896
A13: 20180228 | B13: =DATE(LEFT(A13,4),MID(A13,5,2),RIGHT(A13,2)) -> 43159 | C13: 13.388316 | D13: -1.0858174 | E13: 0.23662159
A14: 20180331 | B14: =DATE(LEFT(A14,4),MID(A14,5,2),RIGHT(A14,2)) -> 43190 | C14: 12.690308 | D14: -1.5136723 | E14: -0.47828595
... A110: 20260331 | B110: =DATE(LEFT(A110,4),MID(A110,5,2),RIGHT(A110,2)) -> 46112 | C110: 7.9 | D110: -0.51762471 | E110: -1.0548119

Sheet M1_YOY_M
A1: publish_date | C1: raw_data | D1: factor_value_level | E1: factor_value_change
A2: 20160731 | B2: =DATE(LEFT(A2,4),MID(A2,5,2),RIGHT(A2,2)) -> 42582 | C2: 25.4 | D2: 2.2181621
A3: 20160831 | B3: =DATE(LEFT(A3,4),MID(A3,5,2),RIGHT(A3,2)) -> 42613 | C3: 25.3 | D3: 1.5771915 | E3: -0.34402599
A4: 20160930 | B4: =DATE(LEFT(A4,4),MID(A4,5,2),RIGHT(A4,2)) -> 42643 | C4: 24.7 | D4: 1.0386968 | E4: -0.43478546
A5: 20161031 | B5: =DATE(LEFT(A5,4),MID(A5,5,2),RIGHT(A5,2)) -> 42674 | C5: 23.9 | D5: 0.5902715 | E5: -0.4096163
A6: 20161130 | B6: =DATE(LEFT(A6,4),MID(A6,5,2),RIGHT(A6,2)) -> 42704 | C6: 22.7 | D6: 0.12286042 | E6: -0.45547843
A7: 20161231 | B7: =DATE(LEFT(A7,4),MID(A7,5,2),RIGHT(A7,2)) -> 42735 | C7: 21.4 | D7: -0.29657539 | E7: -0.38866052
A8: 20170131 | B8: =DATE(LEFT(A8,4),MID(A8,5,2),RIGHT(A8,2)) -> 42766 | C8: 14.5 | D8: -2.2179242 | E8: -2.2723873
A9: 20170228 | B9: =DATE(LEFT(A9,4),MID(A9,5,2),RIGHT(A9,2)) -> 42794 | C9: 21.4 | D9: 0.096185167 | E9: 2.8311438
A10: 20170331 | B10: =DATE(LEFT(A10,4),MID(A10,5,2),RIGHT(A10,2)) -> 42825 | C10: 18.8 | D10: -0.63745943 | E10: -0.68811415
A11: 20170430 | B11: =DATE(LEFT(A11,4),MID(A11,5,2),RIGHT(A11,2)) -> 42855 | C11: 18.5 | D11: -0.62907568 | E11: 0.12462817
A12: 20170531 | B12: =DATE(LEFT(A12,4),MID(A12,5,2),RIGHT(A12,2)) -> 42886 | C12: 17 | D12: -0.94701713 | E12: -0.23278747
A13: 20170630 | B13: =DATE(LEFT(A13,4),MID(A13,5,2),RIGHT(A13,2)) -> 42916 | C13: 15 | D13: -1.3356901 | E13: -0.32274259
A14: 20170731 | B14: =DATE(LEFT(A14,4),MID(A14,5,2),RIGHT(A14,2)) -> 42947 | C14: 15.3 | D14: -1.0059023 | E14: 0.4629468
... A118: 20260331 | B118: =DATE(LEFT(A118,4),MID(A118,5,2),RIGHT(A118,2)) -> 46112 | C118: 5.1 | D118: 0.39466946 | E118: -0.98547485

Sheet M2_YOY_M
A1: publish_date | C1: raw_data | D1: factor_value_level | E1: factor_value_change
A2: 20160731 | B2: =DATE(LEFT(A2,4),MID(A2,5,2),RIGHT(A2,2)) -> 42582 | C2: 10.2 | D2: -2.0190819
A3: 20160831 | B3: =DATE(LEFT(A3,4),MID(A3,5,2),RIGHT(A3,2)) -> 42613 | C3: 11.4 | D3: -0.54930017 | E3: 1.6237568
A4: 20160930 | B4: =DATE(LEFT(A4,4),MID(A4,5,2),RIGHT(A4,2)) -> 42643 | C4: 11.5 | D4: -0.35054078 | E4: 0.20821461
A5: 20161031 | B5: =DATE(LEFT(A5,4),MID(A5,5,2),RIGHT(A5,2)) -> 42674 | C5: 11.6 | D5: -0.18449553 | E5: 0.16900243
A6: 20161130 | B6: =DATE(LEFT(A6,4),MID(A6,5,2),RIGHT(A6,2)) -> 42704 | C6: 11.4 | D6: -0.29488714 | E6: -0.16327645
A7: 20161231 | B7: =DATE(LEFT(A7,4),MID(A7,5,2),RIGHT(A7,2)) -> 42735 | C7: 11.3 | D7: -0.30184717 | E7: -0.036078951
A8: 20170131 | B8: =DATE(LEFT(A8,4),MID(A8,5,2),RIGHT(A8,2)) -> 42766 | C8: 10.7 | D8: -0.74235304 | E8: -0.55471308
A9: 20170228 | B9: =DATE(LEFT(A9,4),MID(A9,5,2),RIGHT(A9,2)) -> 42794 | C9: 10.4 | D9: -0.83809919 | E9: -0.13806105
A10: 20170331 | B10: =DATE(LEFT(A10,4),MID(A10,5,2),RIGHT(A10,2)) -> 42825 | C10: 10.1 | D10: -0.91194104 | E10: -0.11291769
A11: 20170430 | B11: =DATE(LEFT(A11,4),MID(A11,5,2),RIGHT(A11,2)) -> 42855 | C11: 9.8 | D11: -0.96716343 | E11: -0.091430266
A12: 20170531 | B12: =DATE(LEFT(A12,4),MID(A12,5,2),RIGHT(A12,2)) -> 42886 | C12: 9.1 | D12: -1.3629396 | E12: -0.52365081
A13: 20170630 | B13: =DATE(LEFT(A13,4),MID(A13,5,2),RIGHT(A13,2)) -> 42916 | C13: 9.1 | D13: -1.0408946 | E13: 0.37211348
A14: 20170731 | B14: =DATE(LEFT(A14,4),MID(A14,5,2),RIGHT(A14,2)) -> 42947 | C14: 8.9 | D14: -0.96368294 | E14: 0.080715971
... A118: 20260331 | B118: =DATE(LEFT(A118,4),MID(A118,5,2),RIGHT(A118,2)) -> 46112 | C118: 8.5 | D118: 0.62927194 | E118: -1.3201591

Sheet M1M2_DIFF_M
A1: publish_date | C1: raw_data | D1: factor_value_level | E1: factor_value_change
A2: 20160731 | B2: =DATE(LEFT(A2,4),MID(A2,5,2),RIGHT(A2,2)) -> 42582 | C2: =M1_YOY_M!C2-M2_YOY_M!C2 -> 15.2 | D2: 2.7204824
A3: 20160831 | B3: =DATE(LEFT(A3,4),MID(A3,5,2),RIGHT(A3,2)) -> 42613 | C3: =M1_YOY_M!C3-M2_YOY_M!C3 -> 13.9 | D3: 1.5564646 | E3: -0.80479671
A4: 20160930 | B4: =DATE(LEFT(A4,4),MID(A4,5,2),RIGHT(A4,2)) -> 42643 | C4: =M1_YOY_M!C4-M2_YOY_M!C4 -> 13.2 | D4: 1.0175017 | E4: -0.46376871
A5: 20161031 | B5: =DATE(LEFT(A5,4),MID(A5,5,2),RIGHT(A5,2)) -> 42674 | C5: =M1_YOY_M!C5-M2_YOY_M!C5 -> 12.3 | D5: 0.57329258 | E5: -0.42789261
A6: 20161130 | B6: =DATE(LEFT(A6,4),MID(A6,5,2),RIGHT(A6,2)) -> 42704 | C6: =M1_YOY_M!C6-M2_YOY_M!C6 -> 11.3 | D6: 0.19196545 | E6: -0.36595909
A7: 20161231 | B7: =DATE(LEFT(A7,4),MID(A7,5,2),RIGHT(A7,2)) -> 42735 | C7: =M1_YOY_M!C7-M2_YOY_M!C7 -> 10.1 | D7: -0.17597705 | E7: -0.34509979
A8: 20170131 | B8: =DATE(LEFT(A8,4),MID(A8,5,2),RIGHT(A8,2)) -> 42766 | C8: =M1_YOY_M!C8-M2_YOY_M!C8 -> 3.8 | D8: -1.7478851 | E8: -1.9128003
A9: 20170228 | B9: =DATE(LEFT(A9,4),MID(A9,5,2),RIGHT(A9,2)) -> 42794 | C9: =M1_YOY_M!C9-M2_YOY_M!C9 -> 11 | D9: 0.31454849 | E9: 2.7098548
A10: 20170331 | B10: =DATE(LEFT(A10,4),MID(A10,5,2),RIGHT(A10,2)) -> 42825 | C10: =M1_YOY_M!C10-M2_YOY_M!C10 -> 8.7 | D10: -0.33136568 | E10: -0.62719021
A11: 20170430 | B11: =DATE(LEFT(A11,4),MID(A11,5,2),RIGHT(A11,2)) -> 42855 | C11: =M1_YOY_M!C11-M2_YOY_M!C11 -> 8.7 | D11: -0.30821816 | E11: 0.14199069
A12: 20170531 | B12: =DATE(LEFT(A12,4),MID(A12,5,2),RIGHT(A12,2)) -> 42886 | C12: =M1_YOY_M!C12-M2_YOY_M!C12 -> 7.9 | D12: -0.4887966 | E12: -0.090380987
A13: 20170630 | B13: =DATE(LEFT(A13,4),MID(A13,5,2),RIGHT(A13,2)) -> 42916 | C13: =M1_YOY_M!C13-M2_YOY_M!C13 -> 5.9 | D13: -0.9437674 | E13: -0.40245723
A14: 20170731 | B14: =DATE(LEFT(A14,4),MID(A14,5,2),RIGHT(A14,2)) -> 42947 | C14: =M1_YOY_M!C14-M2_YOY_M!C14 -> 6.4 | D14: -0.67167757 | E14: 0.42140111
... A118: 20260331 | B118: =DATE(LEFT(A118,4),MID(A118,5,2),RIGHT(A118,2)) -> 46112 | C118: =M1_YOY_M!C118-M2_YOY_M!C118 -> -3.4 | D118: 0.13894109 | E118: -0.433122

Sheet monthly_data_daily_factor
A1: 日期 | B1: 南华商品指数 | C1: 中间价:美元兑人民币 | D1: 中国:银行间质押式回购加权利率:7天 | E1: 中债国债到期收益率:10年 | F1: 美元指数
A2: Date | B2: NH0100.NHF | C2: M0000185 | D2: M0041653 | E2: S0059749 | F2: USDX.FX
A3: 42004 | B3: 1008.5 | C3: 6.119 | D3: 5.0728 | E3: 3.6219 | F3: 90.27
A4: 42034 | B4: 968.25 | C4: 6.137 | D4: 4.3438 | E4: 3.5019 | F4: 94.8737
A5: 42063 | B5: 1005.59 | C5: 6.1475 | D5: 4.8376 | E5: 3.3602 | F5: 95.25
A6: 42094 | B6: 973.41 | C6: 6.1422 | D6: 3.9764 | E6: 3.6483 | F6: 98.4117
A7: 42124 | B7: 1008.69 | C7: 6.1137 | D7: 2.4202 | E7: 3.3503 | F7: 94.8313
A8: 42153 | B8: 1001.85 | C8: 6.1196 | D8: 1.9866 | E8: 3.5954 | F8: 96.86
A9: 42185 | B9: 950.07 | C9: 6.1136 | D9: 2.8062 | E9: 3.5976 | F9: 95.5016
A10: 42216 | B10: 901.52 | C10: 6.1172 | D10: 2.4751 | E10: 3.4752 | F10: 97.2276
A11: 42247 | B11: 886.91 | C11: 6.3893 | D11: 2.4978 | E11: 3.3252 | F11: 95.9885
A12: 42277 | B12: 870.64 | C12: 6.3613 | D12: 2.3925 | E12: 3.2362 | F12: 96.2692
A13: 42307 | B13: 861.5 | C13: 6.3495 | D13: 2.3821 | E13: 3.06 | F13: 96.8961
A14: 42338 | B14: 821.47 | C14: 6.3962 | D14: 2.4129 | E14: 3.0404 | F14: 100.2351
... A139: 46136 | B139: 3055.53 | C139: 6.8674 | D139: 1.3702 | E139: 1.7601 | F139: 98.5267
